Workbook

Sheet Dashboard
A1: AYA DATA — CRM | U1: All Time
A2: Live view across Inbound, Pipeline & Revenue. All data pulls from Tabs 1-3. Use the ⏱ PERIOD toggle (right) to filter by time. | U2: 2025
A3: 📊 KEY METRICS AT A GLANCE | O3: ⏱ PERIOD ▸ | P3: 2026 | U3: 2026
A4: =COUNTIFS('1. Inbound Leads'!B8:B1000, ">="&U10, '1. Inbound Leads'!B8:B1000, "<="&U12) -> 63 | C4: =COUNTIFS('1. Inbound Leads'!AC8:AC396,"Move to Scoping",'1. Inbound Leads'!B8:B396,">="&U10,'1. Inbound Leads'!B8:B396,"<="&U12) -> 1 | E4: =IFERROR(C4/A4,0) -> 0.015873016 | G4: =COUNTIFS('2. Scoping & PoC'!Y7:Y183,"Scoping",'2. Scoping & PoC'!E7:E183,">="&U10,'2. Scoping & PoC'!E7:E183,"<="&U12)+COUNTIFS('2. Scoping & PoC'!Y7:Y183,"PoC In Progress",'2. Scoping & PoC'!E7:E183,">="&U10,'2. Scoping & PoC'!E7:E183,"<="&U12)+COUNTIFS('2. Scoping & PoC'!Y7:Y183,"PoC Complete",'2. Scoping & PoC'!E7:E183,">="&U10,'2. Scoping & PoC'!E7:E183,"<="&U12) -> 5 | I4: =COUNTIFS('2. Scoping & PoC'!Y7:Y183,"PoC In Progress",'2. Scoping & PoC'!E7:E183,">="&U10,'2. Scoping & PoC'!E7:E183,"<="&U12) -> 0 | K4: =COUNTIFS('2. Scoping & PoC'!Y7:Y183,"Won*",'2. Scoping & PoC'!E7:E183,">="&U10,'2. Scoping & PoC'!E7:E183,"<="&U12) -> 4 | M4: =COUNTIFS('2. Scoping & PoC'!Y7:Y183,"Lost",'2. Scoping & PoC'!E7:E183,">="&U10,'2. Scoping & PoC'!E7:E183,"<="&U12) -> 4 | O4: =IFERROR(K4/(K4+M4),0) -> 0.5 | Q4: {=IFERROR(SUMPRODUCT(('2. Scoping & PoC'!AA6:AA1996<>"")*IF(ISNUMBER('2. Scoping & PoC'!AA6:AA1996),'2. Scoping & PoC'!AA6:AA1996,0)),0)} -> 24000 | S4: =IFERROR(AVERAGE('2. Scoping & PoC'!Z7:Z183),0) -> 0.34 | U4: Last 3 months
A5: Total Inbound Leads | C5: Moved to Scoping | E5: Lead → Scoping % | G5: Active in Scoping | I5: PoCs Running | K5: Deals Won | M5: Deals Lost | O5: Win Rate | Q5: Weighted Pipeline ($) | S5: Avg. Days in Scoping | U5: Last 6 months
U6: YTD 2025
A7: 1 │ INBOUND LEAD VOLUME
A8: Month | B8: Leads | U8: Period Helpers
A9: 2025-01 | B9: =COUNTIFS('1. Inbound Leads'!B8:B203,">="&DATE(2025,1,1),'1. Inbound Leads'!B8:B203,"<"&DATE(2025,2,1)) -> 9 | U9: Start Date
A10: 2025-02 | B10: =COUNTIFS('1. Inbound Leads'!B8:B203,">="&DATE(2025,2,1),'1. Inbound Leads'!B8:B203,"<"&DATE(2025,3,1)) -> 15 | U10: =IF(P3="All Time",DATE(2000,1,1),IF(P3&""="2025",DATE(2025,1,1),IF(P3&""="2026",DATE(2026,1,1),IF(P3="Last 3 months",EDATE(TODAY(),-3),IF(P3="Last 6 months",EDATE(TODAY(),-6),IF(P3="YTD 2025",DATE(2025,1,1),DATE(2000,1,1))))))) -> 46023
A11: 2025-03 | B11: =COUNTIFS('1. Inbound Leads'!B8:B203,">="&DATE(2025,3,1),'1. Inbound Leads'!B8:B203,"<"&DATE(2025,4,1)) -> 9 | U11: End Date
A12: 2025-04 | B12: =COUNTIFS('1. Inbound Leads'!B8:B203,">="&DATE(2025,4,1),'1. Inbound Leads'!B8:B203,"<"&DATE(2025,5,1)) -> 11 | U12: =IF(P3="All Time",DATE(2030,12,31),IF(P3&""="2025",DATE(2025,12,31),IF(P3&""="2026",DATE(2026,12,31),IF(P3="Last 3 months",TODAY(),IF(P3="Last 6 months",TODAY(),IF(P3="YTD 2025",TODAY(),DATE(2030,12,31))))))) -> 46387
A13: 2025-05 | B13: =COUNTIFS('1. Inbound Leads'!B8:B203,">="&DATE(2025,5,1),'1. Inbound Leads'!B8:B203,"<"&DATE(2025,6,1)) -> 17 | U13: Period Label
A14: 2025-06 | B14: =COUNTIFS('1. Inbound Leads'!B8:B203,">="&DATE(2025,6,1),'1. Inbound Leads'!B8:B203,"<"&DATE(2025,7,1)) -> 13 | U14: =P3 -> 2026
A15: 2025-07 | B15: =COUNTIFS('1. Inbound Leads'!B8:B203,">="&DATE(2025,7,1),'1. Inbound Leads'!B8:B203,"<"&DATE(2025,8,1)) -> 14
A16: 2025-08 | B16: =COUNTIFS('1. Inbound Leads'!B8:B203,">="&DATE(2025,8,1),'1. Inbound Leads'!B8:B203,"<"&DATE(2025,9,1)) -> 15
A17: 2025-09 | B17: =COUNTIFS('1. Inbound Leads'!B8:B203,">="&DATE(2025,9,1),'1. Inbound Leads'!B8:B203,"<"&DATE(2025,10,1)) -> 16
A18: 2025-10 | B18: =COUNTIFS('1. Inbound Leads'!B8:B203,">="&DATE(2025,10,1),'1. Inbound Leads'!B8:B203,"<"&DATE(2025,11,1)) -> 23
A19: 2025-11 | B19: =COUNTIFS('1. Inbound Leads'!B8:B203,">="&DATE(2025,11,1),'1. Inbound Leads'!B8:B203,"<"&DATE(2025,12,1)) -> 13
A20: 2025-12 | B20: =COUNTIFS('1. Inbound Leads'!B8:B203,">="&DATE(2025,12,1),'1. Inbound Leads'!B8:B203,"<"&DATE(2026,1,1)) -> 10
A21: 2026-01 | B21: =COUNTIFS('1. Inbound Leads'!B8:B203,">="&DATE(2026,1,1),'1. Inbound Leads'!B8:B203,"<"&DATE(2026,2,1)) -> 15
A22: 2026-02 | B22: =COUNTIFS('1. Inbound Leads'!B8:B396,">="&DATE(2026,2,1),'1. Inbound Leads'!B8:B396,"<"&DATE(2026,3,1)) -> 19
A23: 2026-03 | B23: =COUNTIFS('1. Inbound Leads'!B8:B396,">="&DATE(2026,3,1),'1. Inbound Leads'!B8:B396,"<"&DATE(2026,4,1)) -> 24
A24: 2026-04 | B24: =COUNTIFS('1. Inbound Leads'!B8:B396,">="&DATE(2026,4,1),'1. Inbound Leads'!B8:B396,"<"&DATE(2026,5,1)) -> 5
A25: 2026-05 | B25: =COUNTIFS('1. Inbound Leads'!B8:B203,">="&DATE(2026,5,1),'1. Inbound Leads'!B8:B203,"<"&DATE(2026,6,1)) -> 0
A26: 2026-06 | B26: =COUNTIFS('1. Inbound Leads'!B8:B203,">="&DATE(2026,6,1),'1. Inbound Leads'!B8:B203,"<"&DATE(2026,7,1)) -> 0
A27: 2026-07 | B27: =COUNTIFS('1. Inbound Leads'!B8:B203,">="&DATE(2026,7,1),'1. Inbound Leads'!B8:B203,"<"&DATE(2026,8,1)) -> 0
A28: 2026-08 | B28: =COUNTIFS('1. Inbound Leads'!B8:B203,">="&DATE(2026,8,1),'1. Inbound Leads'!B8:B203,"<"&DATE(2026,9,1)) -> 0
A29: 2026-09 | B29: =COUNTIFS('1. Inbound Leads'!B8:B203,">="&DATE(2026,9,1),'1. Inbound Leads'!B8:B203,"<"&DATE(2026,10,1)) -> 0
A30: 2026-10 | B30: =COUNTIFS('1. Inbound Leads'!B8:B203,">="&DATE(2026,10,1),'1. Inbound Leads'!B8:B203,"<"&DATE(2026,11,1)) -> 0
A31: 2026-11 | B31: =COUNTIFS('1. Inbound Leads'!B8:B203,">="&DATE(2026,11,1),'1. Inbound Leads'!B8:B203,"<"&DATE(2026,12,1)) -> 0
A32: 2026-12 | B32: =COUNTIFS('1. Inbound Leads'!B8:B203,">="&DATE(2026,12,1),'1. Inbound Leads'!B8:B203,"<"&DATE(2027,1,1)) -> 0
A34: 1b │ LEADS BY BUSINESS UNIT
A35: Business Unit | B35: Count | C35: % Share
A36: Annotation | B36: =COUNTIF('1. Inbound Leads'!O8:O451,"Data Annotation") -> 170 | C36: =IFERROR(B36/SUM(B36:B38),0) -> 0.75555556
A37: Solutions | B37: =COUNTIF('1. Inbound Leads'!O8:O451,"AI Solutions") -> 43 | C37: =IFERROR(B37/SUM(B36:B38),0) -> 0.19111111
A38: Partnerships | B38: =COUNTIF('1. Inbound Leads'!O8:O450,"Partnerships") -> 12 | C38: =IFERROR(B38/SUM(B36:B38),0) -> 0.053333333
A40: 1c │ LEADS BY INDUSTRY VERTICAL
A41: Vertical | B41: Count | C41: % Share
A42: Healthcare/Medical | B42: =COUNTIF('1. Inbound Leads'!X8:X396,"Healthcare/Medical") -> 21 | C42: =IFERROR(B42/SUM(B$42:B$51),0) -> 0.27631579
...

Sheet 1. Inbound Leads
A2: All inbound leads are logged here. Fields 1-10 from form. Fields 11-16 after first contact. Fields 17-24 after discovery call. Score auto-calculates. When Stage = "Move to Scoping", copy Lead ID to Pipeline tab.
A3: FROM INBOUND FORM | L3: FIRST TOUCH / TRIAGE | R3: DISCOVERY CALL OUTPUTS | Z3: STAGE GATE & ROUTING | AE3: VELOCITY
A5: Lead ID | B5: Date Received | C5: First Name | D5: Last Name | E5: Phone Number | F5: Email | G5: Company | H5: Role / Title | I5: Country | J5: How They Found Aya | K5: Project Description (from form) | L5: Assigned To | M5: Date First Contacted | N5: Response Status | O5: Business Unit | P5: Service Line | Q5: Partner or Direct | R5: Discovery Call Date | S5: Data Modality | T5: Est. Volume | U5: Budget Range | V5: Timeline / Urgency | W5: Decision Maker? | X5: Industry Vertical | Y5: Discovery Notes | Z5: Lead Score | AA5: Lead Grade | AB5: Discovery Complete? | AC5: Stage | AD5: Outcome / Reason if Lost | AE5: Date Moved to Scoping
A6: Auto: AYA-001 | B6: Auto/Manual | C6: Required | D6: Required | F6: Required | G6: Required | H6: Required | I6: Required | J6: Required | K6: Required | L6: Select team member | M6: Date of 1st email/call | N6: Select status | O6: Data Annotation / AI Solutions | P6: Select service | Q6: Partner / Direct | R6: Date of call | S6: Image/Text/Audio/Video/LiDAR | T6: e.g. 10,000 images | U6: Select range | V6: Select urgency | W6: Yes/No | X6: Select vertical | Y6: Free text notes | Z6: AUTO (0-100) | AA6: AUTO (A-D) | AB6: AUTO flag | AC6: Select stage | AD6: Required if Lost/Dead | AE6: Date or blank
A7: =IF(C7<>"","AYA-"&TEXT(ROW()-5,"000"),"") -> AYA-002 | B7: 37444.931 | C7: Onyekachi | D7: Opara | F7: oparaonyekachi1999@gmail.com | G7: Chibuzor | J7: Google Ads | K7: Play | M7: 37444.931 | N7: No Response | Q7: Direct | Y7: Awaiting feedback - No response | Z7: =IF(C7="","",(IF(OR(P7="Data Annotation",P7="GenAI / LLM Eval",P7="Medical Annotation"),25,IF(OR(P7="AI Consulting",P7="Data Collection"),18,IF(P7<>"",10,0)))+IF(AND(K7<>"",LEN(K7)>50,T7<>""),20,IF(AND(K7<>"",LEN(K7)>20),12,IF(K7<>"",5,0)))+IF(OR(U7="$100k–$500k",U7="$500k+"),20,IF(OR(U7="$25k–$100k"),15,IF(OR(U7="$5k–$25k"),10,IF(U7="$1k–$5k",5,0))))+IF(AND(G7<>"",G7<>"-"),15,IF(G7<>"",8,0))+IF(V7="Immediate (this month)",10,IF(V7="Short-term (1–3 months)",7,IF(V7="Medium (3–6 months)",4,0)))+IF(W7="Yes",10,IF(W7="Unclear",5,0)))) -> 20 | AA7: =IF(Z7="","",IF(Z7>=75,"A",IF(Z7>=50,"B",IF(Z7>=25,"C","D")))) -> D | AB7: =IF(C7="","",IF(AND(R7<>"",S7<>"",U7<>"",V7<>"",W7<>""),"✓ Complete","⚠ MISSING: "&IF(R7="","Call Date, ","")&IF(S7="","Modality, ","")&IF(U7="","Budget, ","")&IF(V7="","Timeline, ","")&IF(W7="","Decision Maker",""))) -> ⚠ MISSING: Call Date, Modality, Budget, Timeline, Decision Maker | AC7: Dead — No Response | AD7: No Response
A8: =IF(C8<>"","AYA-"&TEXT(ROW()-5,"000"),"") -> AYA-003 | B8: 45069 | C8: Emmanuel | D8: Irumva | F8: emmanuelirumva@huzalabs.com | G8: Huzalabs | H8: Lead, Software Projects Management and Acquisition | J8: Website Form | K8: Hello Team, My name is Emmanuel a Lead software project management and the acquisition, and I represent Huzalabs (www.huzalabs.com), a 4IR consultancy firm operating across Rwanda, Kenya, Ethiopia, and the USA. I’m reaching out to explore potential collaboration opportunities with AYA Company in the field of Artificial Intelligence. I will be traveling to Ghana soon and would love to arrange an in-person meeting to discuss how we might work together. At Huzalabs, we’ve delivered large-scale AI a | L8: Seyram | M8: 45069 | N8: Responded — Interested | O8: Data Annotation | Q8: Direct | Y8: Meeting booked via Hachly for Monday, May 26, 2025 at 9:30am GMT | Z8: =IF(C8="","",(IF(OR(P8="Data Annotation",P8="GenAI / LLM Eval",P8="Medical Annotation"),25,IF(OR(P8="AI Consulting",P8="Data Collection"),18,IF(P8<>"",10,0)))+IF(AND(K8<>"",LEN(K8)>50,T8<>""),20,IF(AND(K8<>"",LEN(K8)>20),12,IF(K8<>"",5,0)))+IF(OR(U8="$100k–$500k",U8="$500k+"),20,IF(OR(U8="$25k–$100k"),15,IF(OR(U8="$5k–$25k"),10,IF(U8="$1k–$5k",5,0))))+IF(AND(G8<>"",G8<>"-"),15,IF(G8<>"",8,0))+IF(V8="Immediate (this month)",10,IF(V8="Short-term (1–3 months)",7,IF(V8="Medium (3–6 months)",4,0)))+IF(W8="Yes",10,IF(W8="Unclear",5,0)))) -> 27 | AA8: =IF(Z8="","",IF(Z8>=75,"A",IF(Z8>=50,"B",IF(Z8>=25,"C","D")))) -> C | AB8: =IF(C8="","",IF(AND(R8<>"",S8<>"",U8<>"",V8<>"",W8<>""),"✓ Complete","⚠ MISSING: "&IF(R8="","Call Date, ","")&IF(S8="","Modality, ","")&IF(U8="","Budget, ","")&IF(V8="","Timeline, ","")&IF(W8="","Decision Maker",""))) -> ⚠ MISSING: Call Date, Modality, Budget, Timeline, Decision Maker | AC8: Discovery Complete
A9: =IF(C9<>"","AYA-"&TEXT(ROW()-5,"000"),"") -> AYA-004 | B9: 45101 | C9: Rudraksh | D9: Parmar | F9: rudraksh.parmar@fivesdigital.com | G9: Fives Digital | J9: Referral | K9: Hi Rocco, Rudy here again. Below is a summary of the project and its requirements. We would need you to come back to us with any queries and confirm whether you can support the project as per the outlined needs. In case you can support, we would request you to share your hourly rates for QA resources. ****Project Use case - Behavioral Competency project and to provide a key update.**** The client has emphasized the need for local experts/drivers based in the UK, US, and Germany for the annotatio | L9: Akhil | M9: 45101 | N9: Responded — Interested | O9: Data Annotation | P9: Other Solutions | Q9: Direct | X9: Automotive/AV | Y9: Called Rudy on 24/06 - He was busy and we planeed to reconnect on 25th June. Spoken to Rudy (25/6) - Will share our Questions to Rudy via email. | Z9: =IF(C9="","",(IF(OR(P9="Data Annotation",P9="GenAI / LLM Eval",P9="Medical Annotation"),25,IF(OR(P9="AI Consulting",P9="Data Collection"),18,IF(P9<>"",10,0)))+IF(AND(K9<>"",LEN(K9)>50,T9<>""),20,IF(AND(K9<>"",LEN(K9)>20),12,IF(K9<>"",5,0)))+IF(OR(U9="$100k–$500k",U9="$500k+"),20,IF(OR(U9="$25k–$100k"),15,IF(OR(U9="$5k–$25k"),10,IF(U9="$1k–$5k",5,0))))+IF(AND(G9<>"",G9<>"-"),15,IF(G9<>"",8,0))+IF(V9="Immediate (this month)",10,IF(V9="Short-term (1–3 months)",7,IF(V9="Medium (3–6 months)",4,0)))+IF(W9="Yes",10,IF(W9="Unclear",5,0)))) -> 37 | AA9: =IF(Z9="","",IF(Z9>=75,"A",IF(Z9>=50,"B",IF(Z9>=25,"C","D")))) -> C | AB9: =IF(C9="","",IF(AND(R9<>"",S9<>"",U9<>"",V9<>"",W9<>""),"✓ Complete","⚠ MISSING: "&IF(R9="","Call Date, ","")&IF(S9="","Modality, ","")&IF(U9="","Budget, ","")&IF(V9="","Timeline, ","")&IF(W9="","Decision Maker",""))) -> ⚠ MISSING: Call Date, Modality, Budget, Timeline, Decision Maker | AC9: Contacted
A10: =IF(C10<>"","AYA-"&TEXT(ROW()-5,"000"),"") -> AYA-005 | B10: 45436 | C10: Korede | D10: Bashir | F10: samebashirkorede@gmail.com | G10: People are requesting projects related to product demonstrations and exploring how Aya Grow can assist them. | J10: Website Form | K10: Book A Demo: Interested in reviewing how Aya grow can help me | L10: Other | O10: Data Annotation | P10: CV Annotation | Q10: Direct | Z10: =IF(C10="","",(IF(OR(P10="Data Annotation",P10="GenAI / LLM Eval",P10="Medical Annotation"),25,IF(OR(P10="AI Consulting",P10="Data Collection"),18,IF(P10<>"",10,0)))+IF(AND(K10<>"",LEN(K10)>50,T10<>""),20,IF(AND(K10<>"",LEN(K10)>20),12,IF(K10<>"",5,0)))+IF(OR(U10="$100k–$500k",U10="$500k+"),20,IF(OR(U10="$25k–$100k"),15,IF(OR(U10="$5k–$25k"),10,IF(U10="$1k–$5k",5,0))))+IF(AND(G10<>"",G10<>"-"),15,IF(G10<>"",8,0))+IF(V10="Immediate (this month)",10,IF(V10="Short-term (1–3 months)",7,IF(V10="Medium (3–6 months)",4,0)))+IF(W10="Yes",10,IF(W10="Unclear",5,0)))) -> 37 | AA10: =IF(Z10="","",IF(Z10>=75,"A",IF(Z10>=50,"B",IF(Z10>=25,"C","D")))) -> C | AB10: =IF(C10="","",IF(AND(R10<>"",S10<>"",U10<>"",V10<>"",W10<>""),"✓ Complete","⚠ MISSING: "&IF(R10="","Call Date, ","")&IF(S10="","Modality, ","")&IF(U10="","Budget, ","")&IF(V10="","Timeline, ","")&IF(W10="","Decision Maker",""))) -> ⚠ MISSING: Call Date, Modality, Budget, Timeline, Decision Maker | AC10: New Lead
A11: =IF(C11<>"","AYA-"&TEXT(ROW()-5,"000"),"") -> AYA-006 | B11: 45608 | C11: Abrar | D11: Bilakhiya | F11: abrar@content-whale.com | G11: Content Whale | K11: Live photo collection (images of curved signs, storefronts, logos, documents, posters, etc.), data annotation with labelling (business cards, invoices, flight information, food packaging, etc.): https://docs.google.com/document/d/1mWR6IydQoLnu430JTzUSlbWwbhofHQAo2Cw0BHzCoCs/edit?tab=t.0 | L11: Michael | O11: Data Annotation | P11: Grow Solutions | Q11: Direct | Z11: =IF(C11="","",(IF(OR(P11="Data Annotation",P11="GenAI / LLM Eval",P11="Medical Annotation"),25,IF(OR(P11="AI Consulting",P11="Data Collection"),18,IF(P11<>"",10,0)))+IF(AND(K11<>"",LEN(K11)>50,T11<>""),20,IF(AND(K11<>"",LEN(K11)>20),12,IF(K11<>"",5,0)))+IF(OR(U11="$100k–$500k",U11="$500k+"),20,IF(OR(U11="$25k–$100k"),15,IF(OR(U11="$5k–$25k"),10,IF(U11="$1k–$5k",5,0))))+IF(AND(G11<>"",G11<>"-"),15,IF(G11<>"",8,0))+IF(V11="Immediate (this month)",10,IF(V11="Short-term (1–3 months)",7,IF(V11="Medium (3–6 months)",4,0)))+IF(W11="Yes",10,IF(W11="Unclear",5,0)))) -> 37 | AA11: =IF(Z11="","",IF(Z11>=75,"A",IF(Z11>=50,"B",IF(Z11>=25,"C","D")))) -> C | AB11: =IF(C11="","",IF(AND(R11<>"",S11<>"",U11<>"",V11<>"",W11<>""),"✓ Complete","⚠ MISSING: "&IF(R11="","Call Date, ","")&IF(S11="","Modality, ","")&IF(U11="","Budget, ","")&IF(V11="","Timeline, ","")&IF(W11="","Decision Maker",""))) -> ⚠ MISSING: Call Date, Modality, Budget, Timeline, Decision Maker | AC11: New Lead
A12: =IF(C12<>"","AYA-"&TEXT(ROW()-5,"000"),"") -> AYA-007 | B12: 45608 | C12: Siraj | D12: Damanhouri | F12: Siraj@hopecells.net | G12: HopeCells | K12: Data acquisition (building an AI symptoms checker and a chatbot in Arabic) | L12: Michael | O12: Data Annotation | P12: CV Annotation | Q12: Direct | Z12: =IF(C12="","",(IF(OR(P12="Data Annotation",P12="GenAI / LLM Eval",P12="Medical Annotation"),25,IF(OR(P12="AI Consulting",P12="Data Collection"),18,IF(P12<>"",10,0)))+IF(AND(K12<>"",LEN(K12)>50,T12<>""),20,IF(AND(K12<>"",LEN(K12)>20),12,IF(K12<>"",5,0)))+IF(OR(U12="$100k–$500k",U12="$500k+"),20,IF(OR(U12="$25k–$100k"),15,IF(OR(U12="$5k–$25k"),10,IF(U12="$1k–$5k",5,0))))+IF(AND(G12<>"",G12<>"-"),15,IF(G12<>"",8,0))+IF(V12="Immediate (this month)",10,IF(V12="Short-term (1–3 months)",7,IF(V12="Medium (3–6 months)",4,0)))+IF(W12="Yes",10,IF(W12="Unclear",5,0)))) -> 37 | AA12: =IF(Z12="","",IF(Z12>=75,"A",IF(Z12>=50,"B",IF(Z12>=25,"C","D")))) -> C | AB12: =IF(C12="","",IF(AND(R12<>"",S12<>"",U12<>"",V12<>"",W12<>""),"✓ Complete","⚠ MISSING: "&IF(R12="","Call Date, ","")&IF(S12="","Modality, ","")&IF(U12="","Budget, ","")&IF(V12="","Timeline, ","")&IF(W12="","Decision Maker",""))) -> ⚠ MISSING: Call Date, Modality, Budget, Timeline, Decision Maker | AC12: New Lead
A13: =IF(C13<>"","AYA-"&TEXT(ROW()-5,"000"),"") -> AYA-008 | B13: 45608 | C13: Baffour | D13: Gyawu | F13: baffourthe3rd@gmail.com | K13: Pricing structure for AyaSpeech + availability of API | L13: Olivia | O13: AI Solutions | Q13: Direct | Z13: =IF(C13="","",(IF(OR(P13="Data Annotation",P13="GenAI / LLM Eval",P13="Medical Annotation"),25,IF(OR(P13="AI Consulting",P13="Data Collection"),18,IF(P13<>"",10,0)))+IF(AND(K13<>"",LEN(K13)>50,T13<>""),20,IF(AND(K13<>"",LEN(K13)>20),12,IF(K13<>"",5,0)))+IF(OR(U13="$100k–$500k",U13="$500k+"),20,IF(OR(U13="$25k–$100k"),15,IF(OR(U13="$5k–$25k"),10,IF(U13="$1k–$5k",5,0))))+IF(AND(G13<>"",G13<>"-"),15,IF(G13<>"",8,0))+IF(V13="Immediate (this month)",10,IF(V13="Short-term (1–3 months)",7,IF(V13="Medium (3–6 months)",4,0)))+IF(W13="Yes",10,IF(W13="Unclear",5,0)))) -> 12 | AA13: =IF(Z13="","",IF(Z13>=75,"A",IF(Z13>=50,"B",IF(Z13>=25,"C","D")))) -> D | AB13: =IF(C13="","",IF(AND(R13<>"",S13<>"",U13<>"",V13<>"",W13<>""),"✓ Complete","⚠ MISSING: "&IF(R13="","Call Date, ","")&IF(S13="","Modality, ","")&IF(U13="","Budget, ","")&IF(V13="","Timeline, ","")&IF(W13="","Decision Maker",""))) -> ⚠ MISSING: Call Date, Modality, Budget, Timeline, Decision Maker | AC13: New Lead
A14: =IF(C14<>"","AYA-"&TEXT(ROW()-5,"000"),"") -> AYA-009 | B14: 45615 | C14: Peter | D14: Tokor | F14: peter@phundit.app | G14: Phundit (Peter Tokor) | K14: Fintech startup wanting to leverage AI to build a financial advisor and financial health score - client scheduled meeting for Tue, Nov 19 at 11:30am | L14: Michael | O14: AI Solutions | P14: Speech Solutions | Q14: Direct | Z14: =IF(C14="","",(IF(OR(P14="Data Annotation",P14="GenAI / LLM Eval",P14="Medical Annotation"),25,IF(OR(P14="AI Consulting",P14="Data Collection"),18,IF(P14<>"",10,0)))+IF(AND(K14<>"",LEN(K14)>50,T14<>""),20,IF(AND(K14<>"",LEN(K14)>20),12,IF(K14<>"",5,0)))+IF(OR(U14="$100k–$500k",U14="$500k+"),20,IF(OR(U14="$25k–$100k"),15,IF(OR(U14="$5k–$25k"),10,IF(U14="$1k–$5k",5,0))))+IF(AND(G14<>"",G14<>"-"),15,IF(G14<>"",8,0))+IF(V14="Immediate (this month)",10,IF(V14="Short-term (1–3 months)",7,IF(V14="Medium (3–6 months)",4,0)))+IF(W14="Yes",10,IF(W14="Unclear",5,0)))) -> 37 | AA14: =IF(Z14="","",IF(Z14>=75,"A",IF(Z14>=50,"B",IF(Z14>=25,"C","D")))) -> C | AB14: =IF(C14="","",IF(AND(R14<>"",S14<>"",U14<>"",V14<>"",W14<>""),"✓ Complete","⚠ MISSING: "&IF(R14="","Call Date, ","")&IF(S14="","Modality, ","")&IF(U14="","Budget, ","")&IF(V14="","Timeline, ","")&IF(W14="","Decision Maker",""))) -> ⚠ MISSING: Call Date, Modality, Budget, Timeline, Decision Maker | AC14: New Lead
A15: =IF(C15<>"","AYA-"&TEXT(ROW()-5,"000"),"") -> AYA-010 | B15: 45617.924 | C15: Austine | D15: Mark | F15: austinemark292@gmail.com | G15: Tech company - Austine Mark | J15: Google Ads | K15: Story | M15: 45617.924 | N15: No Response | P15: Other Solutions | Q15: Direct | Y15: Awaiting feedback - No response | Z15: =IF(C15="","",(IF(OR(P15="Data Annotation",P15="GenAI / LLM Eval",P15="Medical Annotation"),25,IF(OR(P15="AI Consulting",P15="Data Collection"),18,IF(P15<>"",10,0)))+IF(AND(K15<>"",LEN(K15)>50,T15<>""),20,IF(AND(K15<>"",LEN(K15)>20),12,IF(K15<>"",5,0)))+IF(OR(U15="$100k–$500k",U15="$500k+"),20,IF(OR(U15="$25k–$100k"),15,IF(OR(U15="$5k–$25k"),10,IF(U15="$1k–$5k",5,0))))+IF(AND(G15<>"",G15<>"-"),15,IF(G15<>"",8,0))+IF(V15="Immediate (this month)",10,IF(V15="Short-term (1–3 months)",7,IF(V15="Medium (3–6 months)",4,0)))+IF(W15="Yes",10,IF(W15="Unclear",5,0)))) -> 30 | AA15: =IF(Z15="","",IF(Z15>=75,"A",IF(Z15>=50,"B",IF(Z15>=25,"C","D")))) -> C | AB15: =IF(C15="","",IF(AND(R15<>"",S15<>"",U15<>"",V15<>"",W15<>""),"✓ Complete","⚠ MISSING: "&IF(R15="","Call Date, ","")&IF(S15="","Modality, ","")&IF(U15="","Budget, ","")&IF(V15="","Timeline, ","")&IF(W15="","Decision Maker",""))) -> ⚠ MISSING: Call Date, Modality, Budget, Timeline, Decision Maker | AC15: Dead — No Response | AD15: No Response
A16: =IF(C16<>"","AYA-"&TEXT(ROW()-5,"000"),"") -> AYA-011 | B16: 45628.296 | C16: Morryna | D16: Sianipar | F16: morrynasianipar@gmail.com | G16: None mo | J16: Google Ads | K16: none | M16: 45628.296 | N16: No Response | Q16: Direct | Y16: Awaiting feedback - No response | Z16: =IF(C16="","",(IF(OR(P16="Data Annotation",P16="GenAI / LLM Eval",P16="Medical Annotation"),25,IF(OR(P16="AI Consulting",P16="Data Collection"),18,IF(P16<>"",10,0)))+IF(AND(K16<>"",LEN(K16)>50,T16<>""),20,IF(AND(K16<>"",LEN(K16)>20),12,IF(K16<>"",5,0)))+IF(OR(U16="$100k–$500k",U16="$500k+"),20,IF(OR(U16="$25k–$100k"),15,IF(OR(U16="$5k–$25k"),10,IF(U16="$1k–$5k",5,0))))+IF(AND(G16<>"",G16<>"-"),15,IF(G16<>"",8,0))+IF(V16="Immediate (this month)",10,IF(V16="Short-term (1–3 months)",7,IF(V16="Medium (3–6 months)",4,0)))+IF(W16="Yes",10,IF(W16="Unclear",5,0)))) -> 20 | AA16: =IF(Z16="","",IF(Z16>=75,"A",IF(Z16>=50,"B",IF(Z16>=25,"C","D")))) -> D | AB16: =IF(C16="","",IF(AND(R16<>"",S16<>"",U16<>"",V16<>"",W16<>""),"✓ Complete","⚠ MISSING: "&IF(R16="","Call Date, ","")&IF(S16="","Modality, ","")&IF(U16="","Budget, ","")&IF(V16="","Timeline, ","")&IF(W16="","Decision Maker",""))) -> ⚠ MISSING: Call Date, Modality, Budget, Timeline, Decision Maker | AC16: Dead — No Response | AD16: No Response
A17: =IF(C17<>"","AYA-"&TEXT(ROW()-5,"000"),"") -> AYA-012 | B17: 45630 | C17: UWAMARIYA | D17: Mediatrice | F17: izeremedia@gmail.com | K17: Free Discovery Session: is to discover essential reason related to geospatial analysis a | L17: Michael | O17: AI Solutions | Q17: Direct | Z17: =IF(C17="","",(IF(OR(P17="Data Annotation",P17="GenAI / LLM Eval",P17="Medical Annotation"),25,IF(OR(P17="AI Consulting",P17="Data Collection"),18,IF(P17<>"",10,0)))+IF(AND(K17<>"",LEN(K17)>50,T17<>""),20,IF(AND(K17<>"",LEN(K17)>20),12,IF(K17<>"",5,0)))+IF(OR(U17="$100k–$500k",U17="$500k+"),20,IF(OR(U17="$25k–$100k"),15,IF(OR(U17="$5k–$25k"),10,IF(U17="$1k–$5k",5,0))))+IF(AND(G17<>"",G17<>"-"),15,IF(G17<>"",8,0))+IF(V17="Immediate (this month)",10,IF(V17="Short-term (1–3 months)",7,IF(V17="Medium (3–6 months)",4,0)))+IF(W17="Yes",10,IF(W17="Unclear",5,0)))) -> 12 | AA17: =IF(Z17="","",IF(Z17>=75,"A",IF(Z17>=50,"B",IF(Z17>=25,"C","D")))) -> D | AB17: =IF(C17="","",IF(AND(R17<>"",S17<>"",U17<>"",V17<>"",W17<>""),"✓ Complete","⚠ MISSING: "&IF(R17="","Call Date, ","")&IF(S17="","Modality, ","")&IF(U17="","Budget, ","")&IF(V17="","Timeline, ","")&IF(W17="","Decision Maker",""))) -> ⚠ MISSING: Call Date, Modality, Budget, Timeline, Decision Maker | AC17: New Lead
A18: =IF(C18<>"","AYA-"&TEXT(ROW()-5,"000"),"") -> AYA-013 | B18: 45644 | C18: Kawya | D18: Jayakody | F18: kawya@orelit.com | G18: Orel IT | K18: Please connect me with someone responsible for partnerships. | L18: Michael | O18: Data Annotation | P18: Other Solutions | Q18: Direct | Z18: =IF(C18="","",(IF(OR(P18="Data Annotation",P18="GenAI / LLM Eval",P18="Medical Annotation"),25,IF(OR(P18="AI Consulting",P18="Data Collection"),18,IF(P18<>"",10,0)))+IF(AND(K18<>"",LEN(K18)>50,T18<>""),20,IF(AND(K18<>"",LEN(K18)>20),12,IF(K18<>"",5,0)))+IF(OR(U18="$100k–$500k",U18="$500k+"),20,IF(OR(U18="$25k–$100k"),15,IF(OR(U18="$5k–$25k"),10,IF(U18="$1k–$5k",5,0))))+IF(AND(G18<>"",G18<>"-"),15,IF(G18<>"",8,0))+IF(V18="Immediate (this month)",10,IF(V18="Short-term (1–3 months)",7,IF(V18="Medium (3–6 months)",4,0)))+IF(W18="Yes",10,IF(W18="Unclear",5,0)))) -> 37 | AA18: =IF(Z18="","",IF(Z18>=75,"A",IF(Z18>=50,"B",IF(Z18>=25,"C","D")))) -> C | AB18: =IF(C18="","",IF(AND(R18<>"",S18<>"",U18<>"",V18<>"",W18<>""),"✓ Complete","⚠ MISSING: "&IF(R18="","Call Date, ","")&IF(S18="","Modality, ","")&IF(U18="","Budget, ","")&IF(V18="","Timeline, ","")&IF(W18="","Decision Maker",""))) -> ⚠ MISSING: Call Date, Modality, Budget, Timeline, Decision Maker | AC18: New Lead
A19: =IF(C19<>"","AYA-"&TEXT(ROW()-5,"000"),"") -> AYA-014 | B19: 45664.612 | C19: Private Hospital | D19: Casablanca | F19: Communication@akdital.ma | G19: Private Hospital Of Casablanca, Aîn Sebaâ. | J19: Google Ads | M19: 45664.612 | N19: No Response | P19: CV Annotation | Q19: Direct | Y19: Awaiting feedback - No response | Z19: =IF(C19="","",(IF(OR(P19="Data Annotation",P19="GenAI / LLM Eval",P19="Medical Annotation"),25,IF(OR(P19="AI Consulting",P19="Data Collection"),18,IF(P19<>"",10,0)))+IF(AND(K19<>"",LEN(K19)>50,T19<>""),20,IF(AND(K19<>"",LEN(K19)>20),12,IF(K19<>"",5,0)))+IF(OR(U19="$100k–$500k",U19="$500k+"),20,IF(OR(U19="$25k–$100k"),15,IF(OR(U19="$5k–$25k"),10,IF(U19="$1k–$5k",5,0))))+IF(AND(G19<>"",G19<>"-"),15,IF(G19<>"",8,0))+IF(V19="Immediate (this month)",10,IF(V19="Short-term (1–3 months)",7,IF(V19="Medium (3–6 months)",4,0)))+IF(W19="Yes",10,IF(W19="Unclear",5,0)))) -> 25 | AA19: =IF(Z19="","",IF(Z19>=75,"A",IF(Z19>=50,"B",IF(Z19>=25,"C","D")))) -> C | AB19: =IF(C19="","",IF(AND(R19<>"",S19<>"",U19<>"",V19<>"",W19<>""),"✓ Complete","⚠ MISSING: "&IF(R19="","Call Date, ","")&IF(S19="","Modality, ","")&IF(U19="","Budget, ","")&IF(V19="","Timeline, ","")&IF(W19="","Decision Maker",""))) -> ⚠ MISSING: Call Date, Modality, Budget, Timeline, Decision Maker | AC19: Dead — No Response | AD19: No Response
A20: =IF(C20<>"","AYA-"&TEXT(ROW()-5,"000"),"") -> AYA-015 | B20: 45666 | C20: Cindy | D20: Abramson | F20: cabramson@lcaconsultancy.com | G20: People are requesting projects related to machine learning data annotation using specific platforms. For AyaData's contact information to direct the RFP, please visit their official website or contact their sales or support team directly through the contact details provided there. | K20: I am assisting a client with their RFP process for a ML data annotation project using their own platform and we would like to invite AyaData to respond. Please provide the contact information where can direct the RFP. | L20: Akhil | M20: 45666 | O20: Data Annotation | Q20: Direct | X20: Automotive/AV | Y20: Reached final selection round with Safely You, but another vendor was chosen. | Z20: =IF(C20="","",(IF(OR(P20="Data Annotation",P20="GenAI / LLM Eval",P20="Medical Annotation"),25,IF(OR(P20="AI Consulting",P20="Data Collection"),18,IF(P20<>"",10,0)))+IF(AND(K20<>"",LEN(K20)>50,T20<>""),20,IF(AND(K20<>"",LEN(K20)>20),12,IF(K20<>"",5,0)))+IF(OR(U20="$100k–$500k",U20="$500k+"),20,IF(OR(U20="$25k–$100k"),15,IF(OR(U20="$5k–$25k"),10,IF(U20="$1k–$5k",5,0))))+IF(AND(G20<>"",G20<>"-"),15,IF(G20<>"",8,0))+IF(V20="Immediate (this month)",10,IF(V20="Short-term (1–3 months)",7,IF(V20="Medium (3–6 months)",4,0)))+IF(W20="Yes",10,IF(W20="Unclear",5,0)))) -> 27 | AA20: =IF(Z20="","",IF(Z20>=75,"A",IF(Z20>=50,"B",IF(Z20>=25,"C","D")))) -> C | AB20: =IF(C20="","",IF(AND(R20<>"",S20<>"",U20<>"",V20<>"",W20<>""),"✓ Complete","⚠ MISSING: "&IF(R20="","Call Date, ","")&IF(S20="","Modality, ","")&IF(U20="","Budget, ","")&IF(V20="","Timeline, ","")&IF(W20="","Decision Maker",""))) -> ⚠ MISSING: Call Date, Modality, Budget, Timeline, Decision Maker | AC20: Dead — Lost to Competitor | AD20: Lost to Competitor
A21: =IF(C21<>"","AYA-"&TEXT(ROW()-5,"000"),"") -> AYA-016 | B21: 45666.235 | C21: Sachin | D21: Kumar | F21: sachin8235kr@gmail.com | G21: Tukan | J21: Google Ads | M21: 45666.235 | N21: No Response | P21: CV Annotation | Q21: Direct | Y21: Awaiting feedback - No response | Z21: =IF(C21="","",(IF(OR(P21="Data Annotation",P21="GenAI / LLM Eval",P21="Medical Annotation"),25,IF(OR(P21="AI Consulting",P21="Data Collection"),18,IF(P21<>"",10,0)))+IF(AND(K21<>"",LEN(K21)>50,T21<>""),20,IF(AND(K21<>"",LEN(K21)>20),12,IF(K21<>"",5,0)))+IF(OR(U21="$100k–$500k",U21="$500k+"),20,IF(OR(U21="$25k–$100k"),15,IF(OR(U21="$5k–$25k"),10,IF(U21="$1k–$5k",5,0))))+IF(AND(G21<>"",G21<>"-"),15,IF(G21<>"",8,0))+IF(V21="Immediate (this month)",10,IF(V21="Short-term (1–3 months)",7,IF(V21="Medium (3–6 months)",4,0)))+IF(W21="Yes",10,IF(W21="Unclear",5,0)))) -> 25 | AA21: =IF(Z21="","",IF(Z21>=75,"A",IF(Z21>=50,"B",IF(Z21>=25,"C","D")))) -> C | AB21: =IF(C21="","",IF(AND(R21<>"",S21<>"",U21<>"",V21<>"",W21<>""),"✓ Complete","⚠ MISSING: "&IF(R21="","Call Date, ","")&IF(S21="","Modality, ","")&IF(U21="","Budget, ","")&IF(V21="","Timeline, ","")&IF(W21="","Decision Maker",""))) -> ⚠ MISSING: Call Date, Modality, Budget, Timeline, Decision Maker | AC21: Dead — No Response | AD21: No Response
A22: =IF(C22<>"","AYA-"&TEXT(ROW()-5,"000"),"") -> AYA-017 | B22: 45669.667 | C22: Stevens | D22: Nolan | F22: 5gt6@packiu.com | G22: Stevens Nolan | J22: Google Ads | M22: 45669.667 | N22: Responded — Not a Fit | Q22: Direct | Y22: Bad Email address/Spam | Z22: =IF(C22="","",(IF(OR(P22="Data Annotation",P22="GenAI / LLM Eval",P22="Medical Annotation"),25,IF(OR(P22="AI Consulting",P22="Data Collection"),18,IF(P22<>"",10,0)))+IF(AND(K22<>"",LEN(K22)>50,T22<>""),20,IF(AND(K22<>"",LEN(K22)>20),12,IF(K22<>"",5,0)))+IF(OR(U22="$100k–$500k",U22="$500k+"),20,IF(OR(U22="$25k–$100k"),15,IF(OR(U22="$5k–$25k"),10,IF(U22="$1k–$5k",5,0))))+IF(AND(G22<>"",G22<>"-"),15,IF(G22<>"",8,0))+IF(V22="Immediate (this month)",10,IF(V22="Short-term (1–3 months)",7,IF(V22="Medium (3–6 months)",4,0)))+IF(W22="Yes",10,IF(W22="Unclear",5,0)))) -> 15 | AA22: =IF(Z22="","",IF(Z22>=75,"A",IF(Z22>=50,"B",IF(Z22>=25,"C","D")))) -> D | AB22: =IF(C22="","",IF(AND(R22<>"",S22<>"",U22<>"",V22<>"",W22<>""),"✓ Complete","⚠ MISSING: "&IF(R22="","Call Date, ","")&IF(S22="","Modality, ","")&IF(U22="","Budget, ","")&IF(V22="","Timeline, ","")&IF(W22="","Decision Maker",""))) -> ⚠ MISSING: Call Date, Modality, Budget, Timeline, Decision Maker | AC22: Dead — Not a Fit | AD22: Spam / Bad Email
A23: =IF(C23<>"","AYA-"&TEXT(ROW()-5,"000"),"") -> AYA-018 | B23: 45670 | C23: Qing | D23: Yang | F23: qing.yang@liangdao.de | G23: I'm unable to access external content, including specific links or messages. Please provide the text or details you need summarized. | K23: Message link: https://chat.google.com/room/AAAAw0s3JqE/kn9IFdVv2u4/kn9IFdVv2u4?cls=10 | L23: Seyram | M23: 45670 | O23: Data Annotation | Q23: Direct | Y23: Partnership Opp - Lost because of Quality Concern and our TPT being the highest | Z23: =IF(C23="","",(IF(OR(P23="Data Annotation",P23="GenAI / LLM Eval",P23="Medical Annotation"),25,IF(OR(P23="AI Consulting",P23="Data Collection"),18,IF(P23<>"",10,0)))+IF(AND(K23<>"",LEN(K23)>50,T23<>""),20,IF(AND(K23<>"",LEN(K23)>20),12,IF(K23<>"",5,0)))+IF(OR(U23="$100k–$500k",U23="$500k+"),20,IF(OR(U23="$25k–$100k"),15,IF(OR(U23="$5k–$25k"),10,IF(U23="$1k–$5k",5,0))))+IF(AND(G23<>"",G23<>"-"),15,IF(G23<>"",8,0))+IF(V23="Immediate (this month)",10,IF(V23="Short-term (1–3 months)",7,IF(V23="Medium (3–6 months)",4,0)))+IF(W23="Yes",10,IF(W23="Unclear",5,0)))) -> 27 | AA23: =IF(Z23="","",IF(Z23>=75,"A",IF(Z23>=50,"B",IF(Z23>=25,"C","D")))) -> C | AB23: =IF(C23="","",IF(AND(R23<>"",S23<>"",U23<>"",V23<>"",W23<>""),"✓ Complete","⚠ MISSING: "&IF(R23="","Call Date, ","")&IF(S23="","Modality, ","")&IF(U23="","Budget, ","")&IF(V23="","Timeline, ","")&IF(W23="","Decision Maker",""))) -> ⚠ MISSING: Call Date, Modality, Budget, Timeline, Decision Maker | AC23: Dead — Lost to Competitor | AD23: Lost to Competitor
A24: =IF(C24<>"","AYA-"&TEXT(ROW()-5,"000"),"") -> AYA-019 | B24: 45670.375 | C24: Henry | D24: Achille | F24: lbsite321@p-store.cc | G24: P Store | J24: Google Ads | M24: 45670.375 | N24: No Response | P24: CV Annotation | Q24: Direct | Y24: Awaiting feedback - No response | Z24: =IF(C24="","",(IF(OR(P24="Data Annotation",P24="GenAI / LLM Eval",P24="Medical Annotation"),25,IF(OR(P24="AI Consulting",P24="Data Collection"),18,IF(P24<>"",10,0)))+IF(AND(K24<>"",LEN(K24)>50,T24<>""),20,IF(AND(K24<>"",LEN(K24)>20),12,IF(K24<>"",5,0)))+IF(OR(U24="$100k–$500k",U24="$500k+"),20,IF(OR(U24="$25k–$100k"),15,IF(OR(U24="$5k–$25k"),10,IF(U24="$1k–$5k",5,0))))+IF(AND(G24<>"",G24<>"-"),15,IF(G24<>"",8,0))+IF(V24="Immediate (this month)",10,IF(V24="Short-term (1–3 months)",7,IF(V24="Medium (3–6 months)",4,0)))+IF(W24="Yes",10,IF(W24="Unclear",5,0)))) -> 25 | AA24: =IF(Z24="","",IF(Z24>=75,"A",IF(Z24>=50,"B",IF(Z24>=25,"C","D")))) -> C | AB24: =IF(C24="","",IF(AND(R24<>"",S24<>"",U24<>"",V24<>"",W24<>""),"✓ Complete","⚠ MISSING: "&IF(R24="","Call Date, ","")&IF(S24="","Modality, ","")&IF(U24="","Budget, ","")&IF(V24="","Timeline, ","")&IF(W24="","Decision Maker",""))) -> ⚠ MISSING: Call Date, Modality, Budget, Timeline, Decision Maker | AC24: Dead — No Response | AD24: No Response
A25: =IF(C25<>"","AYA-"&TEXT(ROW()-5,"000"),"") -> AYA-020 | B25: 45682 | C25: Madhan PM | F25: madhan.p.m.56@gmail.com | G25: People are requesting annotated food image data for an image detection and segmentation project focused on Indian food items. They are inquiring about the availability and cost of existing annotated data, as well as the time and cost for annotating 100-150 food classes with a minimum of 500 images per class. | J25: Search Engine | K25: I am handling a project for a healthcare company and we are working on a image detection and segmentation project for indian based food items. For the above requirement I need annotated food data. Based on this requirement: a) Do you have already annotated data , and what would be the cost? b) If annotating for 100-150 food classes with minimum 500 images for each class, how much time will it take and what would be the cost? | L25: Michael | M25: 45682 | N25: No Response | O25: Data Annotation | P25: Data Collection | Q25: Direct | X25: Healthcare/Medical | Y25: Data Sourcing - Food Data. After 4 follow ups, went quiet on us. | Z25: =IF(C25="","",(IF(OR(P25="Data Annotation",P25="GenAI / LLM Eval",P25="Medical Annotation"),25,IF(OR(P25="AI Consulting",P25="Data Collection"),18,IF(P25<>"",10,0)))+IF(AND(K25<>"",LEN(K25)>50,T25<>""),20,IF(AND(K25<>"",LEN(K25)>20),12,IF(K25<>"",5,0)))+IF(OR(U25="$100k–$500k",U25="$500k+"),20,IF(OR(U25="$25k–$100k"),15,IF(OR(U25="$5k–$25k"),10,IF(U25="$1k–$5k",5,0))))+IF(AND(G25<>"",G25<>"-"),15,IF(G25<>"",8,0))+IF(V25="Immediate (this month)",10,IF(V25="Short-term (1–3 months)",7,IF(V25="Medium (3–6 months)",4,0)))+IF(W25="Yes",10,IF(W25="Unclear",5,0)))) -> 45 | AA25: =IF(Z25="","",IF(Z25>=75,"A",IF(Z25>=50,"B",IF(Z25>=25,"C","D")))) -> C | AB25: =IF(C25="","",IF(AND(R25<>"",S25<>"",U25<>"",V25<>"",W25<>""),"✓ Complete","⚠ MISSING: "&IF(R25="","Call Date, ","")&IF(S25="","Modality, ","")&IF(U25="","Budget, ","")&IF(V25="","Timeline, ","")&IF(W25="","Decision Maker",""))) -> ⚠ MISSING: Call Date, Modality, Budget, Timeline, Decision Maker | AC25: Dead — No Response | AD25: No Response
A26: =IF(C26<>"","AYA-"&TEXT(ROW()-5,"000"),"") -> AYA-021 | B26: 45682 | C26: Andy | D26: Westlake | F26: amwestlake@gmail.com | G26: British Airways | J26: LinkedIn | L26: Michael | M26: 45682 | N26: No Response | O26: Data Annotation | P26: CV Annotation | Q26: Direct | Y26: No Response! | Z26: =IF(C26="","",(IF(OR(P26="Data Annotation",P26="GenAI / LLM Eval",P26="Medical Annotation"),25,IF(OR(P26="AI Consulting",P26="Data Collection"),18,IF(P26<>"",10,0)))+IF(AND(K26<>"",LEN(K26)>50,T26<>""),20,IF(AND(K26<>"",LEN(K26)>20),12,IF(K26<>"",5,0)))+IF(OR(U26="$100k–$500k",U26="$500k+"),20,IF(OR(U26="$25k–$100k"),15,IF(OR(U26="$5k–$25k"),10,IF(U26="$1k–$5k",5,0))))+IF(AND(G26<>"",G26<>"-"),15,IF(G26<>"",8,0))+IF(V26="Immediate (this month)",10,IF(V26="Short-term (1–3 months)",7,IF(V26="Medium (3–6 months)",4,0)))+IF(W26="Yes",10,IF(W26="Unclear",5,0)))) -> 25 | AA26: =IF(Z26="","",IF(Z26>=75,"A",IF(Z26>=50,"B",IF(Z26>=25,"C","D")))) -> C | AB26: =IF(C26="","",IF(AND(R26<>"",S26<>"",U26<>"",V26<>"",W26<>""),"✓ Complete","⚠ MISSING: "&IF(R26="","Call Date, ","")&IF(S26="","Modality, ","")&IF(U26="","Budget, ","")&IF(V26="","Timeline, ","")&IF(W26="","Decision Maker",""))) -> ⚠ MISSING: Call Date, Modality, Budget, Timeline, Decision Maker | AC26: Dead — No Response | AD26: No Response
A27: =IF(C27<>"","AYA-"&TEXT(ROW()-5,"000"),"") -> AYA-022 | B27: 45687.674 | C27: Kevin | D27: Smoot | F27: ksmoot@adhealthcare.com | G27: Advanced Diagnostics Healthcare System | J27: Google Ads | M27: 45687.674 | N27: No Response | Q27: Direct | Y27: Awaiting feedback - No response | Z27: =IF(C27="","",(IF(OR(P27="Data Annotation",P27="GenAI / LLM Eval",P27="Medical Annotation"),25,IF(OR(P27="AI Consulting",P27="Data Collection"),18,IF(P27<>"",10,0)))+IF(AND(K27<>"",LEN(K27)>50,T27<>""),20,IF(AND(K27<>"",LEN(K27)>20),12,IF(K27<>"",5,0)))+IF(OR(U27="$100k–$500k",U27="$500k+"),20,IF(OR(U27="$25k–$100k"),15,IF(OR(U27="$5k–$25k"),10,IF(U27="$1k–$5k",5,0))))+IF(AND(G27<>"",G27<>"-"),15,IF(G27<>"",8,0))+IF(V27="Immediate (this month)",10,IF(V27="Short-term (1–3 months)",7,IF(V27="Medium (3–6 months)",4,0)))+IF(W27="Yes",10,IF(W27="Unclear",5,0)))) -> 15 | AA27: =IF(Z27="","",IF(Z27>=75,"A",IF(Z27>=50,"B",IF(Z27>=25,"C","D")))) -> D | AB27: =IF(C27="","",IF(AND(R27<>"",S27<>"",U27<>"",V27<>"",W27<>""),"✓ Complete","⚠ MISSING: "&IF(R27="","Call Date, ","")&IF(S27="","Modality, ","")&IF(U27="","Budget, ","")&IF(V27="","Timeline, ","")&IF(W27="","Decision Maker",""))) -> ⚠ MISSING: Call Date, Modality, Budget, Timeline, Decision Maker | AC27: Dead — No Response | AD27: No Response
A28: =IF(C28<>"","AYA-"&TEXT(ROW()-5,"000"),"") -> AYA-023 | B28: 45689 | C28: Abdulaziz | F28: alnassar7@hotmail.com | G28: Thakaa Med.ai | J28: LinkedIn | K28: I am currently working on annotating chest x-ray images through segmentation methods. i would like support on providing experts that can annotate these images and segment the findings within these x-rays. my goal is annotating roughly 3000 images with various chest x-ray findings within a 1 month period. I also want to know if you can provide finding-specific datasets for various chest conditions such as consolidation, nodules, pneumothorax etc. I am kindly requesting for the pricing of these se | L28: Michael | M28: 45689 | O28: Data Annotation | P28: Medical AI Annotation | Q28: Direct | X28: Healthcare/Medical | Y28: Data Annotaiton - POC Completed. Client decided to put the project on hold. | Z28: =IF(C28="","",(IF(OR(P28="Data Annotation",P28="GenAI / LLM Eval",P28="Medical Annotation"),25,IF(OR(P28="AI Consulting",P28="Data Collection"),18,IF(P28<>"",10,0)))+IF(AND(K28<>"",LEN(K28)>50,T28<>""),20,IF(AND(K28<>"",LEN(K28)>20),12,IF(K28<>"",5,0)))+IF(OR(U28="$100k–$500k",U28="$500k+"),20,IF(OR(U28="$25k–$100k"),15,IF(OR(U28="$5k–$25k"),10,IF(U28="$1k–$5k",5,0))))+IF(AND(G28<>"",G28<>"-"),15,IF(G28<>"",8,0))+IF(V28="Immediate (this month)",10,IF(V28="Short-term (1–3 months)",7,IF(V28="Medium (3–6 months)",4,0)))+IF(W28="Yes",10,IF(W28="Unclear",5,0)))) -> 37 | AA28: =IF(Z28="","",IF(Z28>=75,"A",IF(Z28>=50,"B",IF(Z28>=25,"C","D")))) -> C | AB28: =IF(C28="","",IF(AND(R28<>"",S28<>"",U28<>"",V28<>"",W28<>""),"✓ Complete","⚠ MISSING: "&IF(R28="","Call Date, ","")&IF(S28="","Modality, ","")&IF(U28="","Budget, ","")&IF(V28="","Timeline, ","")&IF(W28="","Decision Maker",""))) -> ⚠ MISSING: Call Date, Modality, Budget, Timeline, Decision Maker | AC28: Dead — No Budget | AD28: Project on Hold
A29: =IF(C29<>"","AYA-"&TEXT(ROW()-5,"000"),"") -> AYA-024 | B29: 45691.593 | C29: Luminis | D29: Health | F29: info@luminishealth.org | G29: Luminis Health Anne Arundel Medical Center | J29: Google Ads | M29: 45691.593 | N29: Responded — Not a Fit | Q29: Direct | Y29: Bad Email address/Spam | Z29: =IF(C29="","",(IF(OR(P29="Data Annotation",P29="GenAI / LLM Eval",P29="Medical Annotation"),25,IF(OR(P29="AI Consulting",P29="Data Collection"),18,IF(P29<>"",10,0)))+IF(AND(K29<>"",LEN(K29)>50,T29<>""),20,IF(AND(K29<>"",LEN(K29)>20),12,IF(K29<>"",5,0)))+IF(OR(U29="$100k–$500k",U29="$500k+"),20,IF(OR(U29="$25k–$100k"),15,IF(OR(U29="$5k–$25k"),10,IF(U29="$1k–$5k",5,0))))+IF(AND(G29<>"",G29<>"-"),15,IF(G29<>"",8,0))+IF(V29="Immediate (this month)",10,IF(V29="Short-term (1–3 months)",7,IF(V29="Medium (3–6 months)",4,0)))+IF(W29="Yes",10,IF(W29="Unclear",5,0)))) -> 15 | AA29: =IF(Z29="","",IF(Z29>=75,"A",IF(Z29>=50,"B",IF(Z29>=25,"C","D")))) -> D | AB29: =IF(C29="","",IF(AND(R29<>"",S29<>"",U29<>"",V29<>"",W29<>""),"✓ Complete","⚠ MISSING: "&IF(R29="","Call Date, ","")&IF(S29="","Modality, ","")&IF(U29="","Budget, ","")&IF(V29="","Timeline, ","")&IF(W29="","Decision Maker",""))) -> ⚠ MISSING: Call Date, Modality, Budget, Timeline, Decision Maker | AC29: Dead — Not a Fit | AD29: Spam / Bad Email
A30: =IF(C30<>"","AYA-"&TEXT(ROW()-5,"000"),"") -> AYA-025 | B30: 45693.542 | C30: Upper hill | D30: Medical | F30: admin@uhmc.co.ke | G30: Upper hill Medical Center | J30: Google Ads | K30: We are looking at ways to make our data more fluid | M30: 45693.542 | N30: No Response | Q30: Direct | Y30: Awaiting feedback - No response | Z30: =IF(C30="","",(IF(OR(P30="Data Annotation",P30="GenAI / LLM Eval",P30="Medical Annotation"),25,IF(OR(P30="AI Consulting",P30="Data Collection"),18,IF(P30<>"",10,0)))+IF(AND(K30<>"",LEN(K30)>50,T30<>""),20,IF(AND(K30<>"",LEN(K30)>20),12,IF(K30<>"",5,0)))+IF(OR(U30="$100k–$500k",U30="$500k+"),20,IF(OR(U30="$25k–$100k"),15,IF(OR(U30="$5k–$25k"),10,IF(U30="$1k–$5k",5,0))))+IF(AND(G30<>"",G30<>"-"),15,IF(G30<>"",8,0))+IF(V30="Immediate (this month)",10,IF(V30="Short-term (1–3 months)",7,IF(V30="Medium (3–6 months)",4,0)))+IF(W30="Yes",10,IF(W30="Unclear",5,0)))) -> 27 | AA30: =IF(Z30="","",IF(Z30>=75,"A",IF(Z30>=50,"B",IF(Z30>=25,"C","D")))) -> C | AB30: =IF(C30="","",IF(AND(R30<>"",S30<>"",U30<>"",V30<>"",W30<>""),"✓ Complete","⚠ MISSING: "&IF(R30="","Call Date, ","")&IF(S30="","Modality, ","")&IF(U30="","Budget, ","")&IF(V30="","Timeline, ","")&IF(W30="","Decision Maker",""))) -> ⚠ MISSING: Call Date, Modality, Budget, Timeline, Decision Maker | AC30: Dead — No Response | AD30: No Response
A31: =IF(C31<>"","AYA-"&TEXT(ROW()-5,"000"),"") -> AYA-026 | B31: 45694 | C31: Thuy | F31: thuyvt@hikaribpo.com.vn | G31: Hikari BPO Solutions | J31: Cold Outreach | K31: Our company is a Japanese-invested enterprise that located in Danang city, Vietnam. We now process around 20 projects every day. Annually, from January to March, our team can expand to over 250 members. Our client list includes the reputed organizations in Japan, US, UK, China, India, Korea, Vietnam, etc. We not only provide data entry services, but also data annotation, ITO, RPA, and HR services. We are eager to explore how we can work together to achieve mutual success. | L31: Seyram | M31: 45694 | N31: Responded — Not a Fit | O31: Data Annotation | P31: CV Annotation | Q31: Direct | Y31: Not a fit! | Z31: =IF(C31="","",(IF(OR(P31="Data Annotation",P31="GenAI / LLM Eval",P31="Medical Annotation"),25,IF(OR(P31="AI Consulting",P31="Data Collection"),18,IF(P31<>"",10,0)))+IF(AND(K31<>"",LEN(K31)>50,T31<>""),20,IF(AND(K31<>"",LEN(K31)>20),12,IF(K31<>"",5,0)))+IF(OR(U31="$100k–$500k",U31="$500k+"),20,IF(OR(U31="$25k–$100k"),15,IF(OR(U31="$5k–$25k"),10,IF(U31="$1k–$5k",5,0))))+IF(AND(G31<>"",G31<>"-"),15,IF(G31<>"",8,0))+IF(V31="Immediate (this month)",10,IF(V31="Short-term (1–3 months)",7,IF(V31="Medium (3–6 months)",4,0)))+IF(W31="Yes",10,IF(W31="Unclear",5,0)))) -> 37 | AA31: =IF(Z31="","",IF(Z31>=75,"A",IF(Z31>=50,"B",IF(Z31>=25,"C","D")))) -> C | AB31: =IF(C31="","",IF(AND(R31<>"",S31<>"",U31<>"",V31<>"",W31<>""),"✓ Complete","⚠ MISSING: "&IF(R31="","Call Date, ","")&IF(S31="","Modality, ","")&IF(U31="","Budget, ","")&IF(V31="","Timeline, ","")&IF(W31="","Decision Maker",""))) -> ⚠ MISSING: Call Date, Modality, Budget, Timeline, Decision Maker | AC31: Dead — Not a Fit | AD31: Not a Fit
A32: =IF(C32<>"","AYA-"&TEXT(ROW()-5,"000"),"") -> AYA-027 | B32: 45695 | C32: Balram | D32: Dave | F32: balram@cohortdata.com | G32: Cohort Data | J32: LinkedIn | K32: We need OTS audio data collection for 34 different languages. | M32: 45695 | N32: Responded — Not a Fit | O32: Data Annotation | P32: Data Collection | Q32: Direct | X32: Other | Y32: Not a fit! | Z32: =IF(C32="","",(IF(OR(P32="Data Annotation",P32="GenAI / LLM Eval",P32="Medical Annotation"),25,IF(OR(P32="AI Consulting",P32="Data Collection"),18,IF(P32<>"",10,0)))+IF(AND(K32<>"",LEN(K32)>50,T32<>""),20,IF(AND(K32<>"",LEN(K32)>20),12,IF(K32<>"",5,0)))+IF(OR(U32="$100k–$500k",U32="$500k+"),20,IF(OR(U32="$25k–$100k"),15,IF(OR(U32="$5k–$25k"),10,IF(U32="$1k–$5k",5,0))))+IF(AND(G32<>"",G32<>"-"),15,IF(G32<>"",8,0))+IF(V32="Immediate (this month)",10,IF(V32="Short-term (1–3 months)",7,IF(V32="Medium (3–6 months)",4,0)))+IF(W32="Yes",10,IF(W32="Unclear",5,0)))) -> 45 | AA32: =IF(Z32="","",IF(Z32>=75,"A",IF(Z32>=50,"B",IF(Z32>=25,"C","D")))) -> C | AB32: =IF(C32="","",IF(AND(R32<>"",S32<>"",U32<>"",V32<>"",W32<>""),"✓ Complete","⚠ MISSING: "&IF(R32="","Call Date, ","")&IF(S32="","Modality, ","")&IF(U32="","Budget, ","")&IF(V32="","Timeline, ","")&IF(W32="","Decision Maker",""))) -> ⚠ MISSING: Call Date, Modality, Budget, Timeline, Decision Maker | AC32: Dead — Not a Fit | AD32: Not a Fit
A33: =IF(C33<>"","AYA-"&TEXT(ROW()-5,"000"),"") -> AYA-028 | B33: 45695.678 | C33: Prudence | D33: Persson | F33: prudence.persson@manjehealth.com | G33: Manje Health | J33: Google Ads | K33: Tell me more. | M33: 45695.678 | N33: No Response | Q33: Direct | Y33: Awaiting feedback - No response | Z33: =IF(C33="","",(IF(OR(P33="Data Annotation",P33="GenAI / LLM Eval",P33="Medical Annotation"),25,IF(OR(P33="AI Consulting",P33="Data Collection"),18,IF(P33<>"",10,0)))+IF(AND(K33<>"",LEN(K33)>50,T33<>""),20,IF(AND(K33<>"",LEN(K33)>20),12,IF(K33<>"",5,0)))+IF(OR(U33="$100k–$500k",U33="$500k+"),20,IF(OR(U33="$25k–$100k"),15,IF(OR(U33="$5k–$25k"),10,IF(U33="$1k–$5k",5,0))))+IF(AND(G33<>"",G33<>"-"),15,IF(G33<>"",8,0))+IF(V33="Immediate (this month)",10,IF(V33="Short-term (1–3 months)",7,IF(V33="Medium (3–6 months)",4,0)))+IF(W33="Yes",10,IF(W33="Unclear",5,0)))) -> 20 | AA33: =IF(Z33="","",IF(Z33>=75,"A",IF(Z33>=50,"B",IF(Z33>=25,"C","D")))) -> D | AB33: =IF(C33="","",IF(AND(R33<>"",S33<>"",U33<>"",V33<>"",W33<>""),"✓ Complete","⚠ MISSING: "&IF(R33="","Call Date, ","")&IF(S33="","Modality, ","")&IF(U33="","Budget, ","")&IF(V33="","Timeline, ","")&IF(W33="","Decision Maker",""))) -> ⚠ MISSING: Call Date, Modality, Budget, Timeline, Decision Maker | AC33: Dead — No Response | AD33: No Response
A34: =IF(C34<>"","AYA-"&TEXT(ROW()-5,"000"),"") -> AYA-029 | B34: 45698 | C34: Mayukh | D34: Kundu | F34: mayukh@quantigo.ai | G34: Quantigo | J34: Search Engine | K34: We are interested in collaborating with you on our current and upcoming projects in the areas of GenAI, LLM, NLP, data collection, transcription, and translation. To help us handle some of the prestigious projects, we are searching for a reliable partner. Additionally, I sent an email with the information and requested you to complete the Google form in order to obtain all the necessary information. After you submit the Google Form, our concerned team will review it and take the necessary action | L34: Seyram | M34: 45698 | N34: Responded — Interested | O34: Data Annotation | P34: Medical AI Annotation | Q34: Direct | Y34: Signed an NDA - Partnership Opp for GenAI projects | Z34: =IF(C34="","",(IF(OR(P34="Data Annotation",P34="GenAI / LLM Eval",P34="Medical Annotation"),25,IF(OR(P34="AI Consulting",P34="Data Collection"),18,IF(P34<>"",10,0)))+IF(AND(K34<>"",LEN(K34)>50,T34<>""),20,IF(AND(K34<>"",LEN(K34)>20),12,IF(K34<>"",5,0)))+IF(OR(U34="$100k–$500k",U34="$500k+"),20,IF(OR(U34="$25k–$100k"),15,IF(OR(U34="$5k–$25k"),10,IF(U34="$1k–$5k",5,0))))+IF(AND(G34<>"",G34<>"-"),15,IF(G34<>"",8,0))+IF(V34="Immediate (this month)",10,IF(V34="Short-term (1–3 months)",7,IF(V34="Medium (3–6 months)",4,0)))+IF(W34="Yes",10,IF(W34="Unclear",5,0)))) -> 37 | AA34: =IF(Z34="","",IF(Z34>=75,"A",IF(Z34>=50,"B",IF(Z34>=25,"C","D")))) -> C | AB34: =IF(C34="","",IF(AND(R34<>"",S34<>"",U34<>"",V34<>"",W34<>""),"✓ Complete","⚠ MISSING: "&IF(R34="","Call Date, ","")&IF(S34="","Modality, ","")&IF(U34="","Budget, ","")&IF(V34="","Timeline, ","")&IF(W34="","Decision Maker",""))) -> ⚠ MISSING: Call Date, Modality, Budget, Timeline, Decision Maker | AC34: Move to Scoping
A35: =IF(C35<>"","AYA-"&TEXT(ROW()-5,"000"),"") -> AYA-030 | B35: 45698 | C35: Liesbet | D35: Conings | F35: liesbet.conings@xenomatix.com | G35: Xenomatix | J35: Search Engine | K35: We are a Belgium based lidar company (www.xenomatix.com). We are in search of a data annotation company to help us progress our AI applications. Our AI application is taillored to detecting cracks in road pavements. I am interested to understand your data annotation services and how they can support us in accelerating our development. Best regards, Liesbet, Dir of Engineering | L35: Michael | M35: 45698 | N35: No Response | O35: Data Annotation | P35: Other Solutions | Q35: Direct | X35: Automotive/AV | Y35: Good Fit! 4 Follow Ups - Went Quiet! | Z35: =IF(C35="","",(IF(OR(P35="Data Annotation",P35="GenAI / LLM Eval",P35="Medical Annotation"),25,IF(OR(P35="AI Consulting",P35="Data Collection"),18,IF(P35<>"",10,0)))+IF(AND(K35<>"",LEN(K35)>50,T35<>""),20,IF(AND(K35<>"",LEN(K35)>20),12,IF(K35<>"",5,0)))+IF(OR(U35="$100k–$500k",U35="$500k+"),20,IF(OR(U35="$25k–$100k"),15,IF(OR(U35="$5k–$25k"),10,IF(U35="$1k–$5k",5,0))))+IF(AND(G35<>"",G35<>"-"),15,IF(G35<>"",8,0))+IF(V35="Immediate (this month)",10,IF(V35="Short-term (1–3 months)",7,IF(V35="Medium (3–6 months)",4,0)))+IF(W35="Yes",10,IF(W35="Unclear",5,0)))) -> 37 | AA35: =IF(Z35="","",IF(Z35>=75,"A",IF(Z35>=50,"B",IF(Z35>=25,"C","D")))) -> C | AB35: =IF(C35="","",IF(AND(R35<>"",S35<>"",U35<>"",V35<>"",W35<>""),"✓ Complete","⚠ MISSING: "&IF(R35="","Call Date, ","")&IF(S35="","Modality, ","")&IF(U35="","Budget, ","")&IF(V35="","Timeline, ","")&IF(W35="","Decision Maker",""))) -> ⚠ MISSING: Call Date, Modality, Budget, Timeline, Decision Maker | AC35: Dead — No Response | AD35: No Response
A36: =IF(C36<>"","AYA-"&TEXT(ROW()-5,"000"),"") -> AYA-031 | B36: 45698.486 | C36: Hetka | D36: Adrien | F36: hetka@foxnew.info | G36: FOX News | J36: Google Ads | M36: 45698.486 | N36: No Response | P36: Speech Solutions | Q36: Direct | Y36: Awaiting feedback - No response | Z36: =IF(C36="","",(IF(OR(P36="Data Annotation",P36="GenAI / LLM Eval",P36="Medical Annotation"),25,IF(OR(P36="AI Consulting",P36="Data Collection"),18,IF(P36<>"",10,0)))+IF(AND(K36<>"",LEN(K36)>50,T36<>""),20,IF(AND(K36<>"",LEN(K36)>20),12,IF(K36<>"",5,0)))+IF(OR(U36="$100k–$500k",U36="$500k+"),20,IF(OR(U36="$25k–$100k"),15,IF(OR(U36="$5k–$25k"),10,IF(U36="$1k–$5k",5,0))))+IF(AND(G36<>"",G36<>"-"),15,IF(G36<>"",8,0))+IF(V36="Immediate (this month)",10,IF(V36="Short-term (1–3 months)",7,IF(V36="Medium (3–6 months)",4,0)))+IF(W36="Yes",10,IF(W36="Unclear",5,0)))) -> 25 | AA36: =IF(Z36="","",IF(Z36>=75,"A",IF(Z36>=50,"B",IF(Z36>=25,"C","D")))) -> C | AB36: =IF(C36="","",IF(AND(R36<>"",S36<>"",U36<>"",V36<>"",W36<>""),"✓ Complete","⚠ MISSING: "&IF(R36="","Call Date, ","")&IF(S36="","Modality, ","")&IF(U36="","Budget, ","")&IF(V36="","Timeline, ","")&IF(W36="","Decision Maker",""))) -> ⚠ MISSING: Call Date, Modality, Budget, Timeline, Decision Maker | AC36: Dead — No Response | AD36: No Response
A37: =IF(C37<>"","AYA-"&TEXT(ROW()-5,"000"),"") -> AYA-032 | B37: 45699.423 | C37: Chapel | D37: Medical | F37: chapelmpooh.berks@nhs.net | G37: The Chapel Medical Centre | J37: Google Ads | M37: 45699.423 | N37: No Response | P37: Other Solutions | Q37: Direct | Y37: Awaiting feedback - No response | Z37: =IF(C37="","",(IF(OR(P37="Data Annotation",P37="GenAI / LLM Eval",P37="Medical Annotation"),25,IF(OR(P37="AI Consulting",P37="Data Collection"),18,IF(P37<>"",10,0)))+IF(AND(K37<>"",LEN(K37)>50,T37<>""),20,IF(AND(K37<>"",LEN(K37)>20),12,IF(K37<>"",5,0)))+IF(OR(U37="$100k–$500k",U37="$500k+"),20,IF(OR(U37="$25k–$100k"),15,IF(OR(U37="$5k–$25k"),10,IF(U37="$1k–$5k",5,0))))+IF(AND(G37<>"",G37<>"-"),15,IF(G37<>"",8,0))+IF(V37="Immediate (this month)",10,IF(V37="Short-term (1–3 months)",7,IF(V37="Medium (3–6 months)",4,0)))+IF(W37="Yes",10,IF(W37="Unclear",5,0)))) -> 25 | AA37: =IF(Z37="","",IF(Z37>=75,"A",IF(Z37>=50,"B",IF(Z37>=25,"C","D")))) -> C | AB37: =IF(C37="","",IF(AND(R37<>"",S37<>"",U37<>"",V37<>"",W37<>""),"✓ Complete","⚠ MISSING: "&IF(R37="","Call Date, ","")&IF(S37="","Modality, ","")&IF(U37="","Budget, ","")&IF(V37="","Timeline, ","")&IF(W37="","Decision Maker",""))) -> ⚠ MISSING: Call Date, Modality, Budget, Timeline, Decision Maker | AC37: Dead — No Response | AD37: No Response
A38: =IF(C38<>"","AYA-"&TEXT(ROW()-5,"000"),"") -> AYA-033 | B38: 45700 | C38: Mahir | D38: Shariyer | F38: mahirshariyer03@gmail.com | G38: Quantum Label AI | J38: LinkedIn | K38: we are interested to collaborate with Aya Data's team | L38: Seyram | M38: 45700 | N38: No Response | O38: Data Annotation | P38: LiDAR Annotation | Q38: Direct | Y38: No Update! | Z38: =IF(C38="","",(IF(OR(P38="Data Annotation",P38="GenAI / LLM Eval",P38="Medical Annotation"),25,IF(OR(P38="AI Consulting",P38="Data Collection"),18,IF(P38<>"",10,0)))+IF(AND(K38<>"",LEN(K38)>50,T38<>""),20,IF(AND(K38<>"",LEN(K38)>20),12,IF(K38<>"",5,0)))+IF(OR(U38="$100k–$500k",U38="$500k+"),20,IF(OR(U38="$25k–$100k"),15,IF(OR(U38="$5k–$25k"),10,IF(U38="$1k–$5k",5,0))))+IF(AND(G38<>"",G38<>"-"),15,IF(G38<>"",8,0))+IF(V38="Immediate (this month)",10,IF(V38="Short-term (1–3 months)",7,IF(V38="Medium (3–6 months)",4,0)))+IF(W38="Yes",10,IF(W38="Unclear",5,0)))) -> 37 | AA38: =IF(Z38="","",IF(Z38>=75,"A",IF(Z38>=50,"B",IF(Z38>=25,"C","D")))) -> C | AB38: =IF(C38="","",IF(AND(R38<>"",S38<>"",U38<>"",V38<>"",W38<>""),"✓ Complete","⚠ MISSING: "&IF(R38="","Call Date, ","")&IF(S38="","Modality, ","")&IF(U38="","Budget, ","")&IF(V38="","Timeline, ","")&IF(W38="","Decision Maker",""))) -> ⚠ MISSING: Call Date, Modality, Budget, Timeline, Decision Maker | AC38: Dead — No Response | AD38: No Response
A39: =IF(C39<>"","AYA-"&TEXT(ROW()-5,"000"),"") -> AYA-034 | B39: 45708 | C39: Rachel | D39: Kim | F39: dahyun.kim@flitto.com | G39: Flitto | J39: Search Engine | K39: We are reaching out to you about an opportunity to participate in our new project: Voice Recording Project. This task involves recording of daily utterances in a specific language and providing the corresponding transcript for each utterance. [full description in marketing chat] | L39: Akhil | M39: 45708 | N39: Responded — Not a Fit | O39: Data Annotation | P39: Medical AI Annotation | Q39: Direct | X39: Other | Y39: Not a fit! 20 Odd languages! | Z39: =IF(C39="","",(IF(OR(P39="Data Annotation",P39="GenAI / LLM Eval",P39="Medical Annotation"),25,IF(OR(P39="AI Consulting",P39="Data Collection"),18,IF(P39<>"",10,0)))+IF(AND(K39<>"",LEN(K39)>50,T39<>""),20,IF(AND(K39<>"",LEN(K39)>20),12,IF(K39<>"",5,0)))+IF(OR(U39="$100k–$500k",U39="$500k+"),20,IF(OR(U39="$25k–$100k"),15,IF(OR(U39="$5k–$25k"),10,IF(U39="$1k–$5k",5,0))))+IF(AND(G39<>"",G39<>"-"),15,IF(G39<>"",8,0))+IF(V39="Immediate (this month)",10,IF(V39="Short-term (1–3 months)",7,IF(V39="Medium (3–6 months)",4,0)))+IF(W39="Yes",10,IF(W39="Unclear",5,0)))) -> 37 | AA39: =IF(Z39="","",IF(Z39>=75,"A",IF(Z39>=50,"B",IF(Z39>=25,"C","D")))) -> C | AB39: =IF(C39="","",IF(AND(R39<>"",S39<>"",U39<>"",V39<>"",W39<>""),"✓ Complete","⚠ MISSING: "&IF(R39="","Call Date, ","")&IF(S39="","Modality, ","")&IF(U39="","Budget, ","")&IF(V39="","Timeline, ","")&IF(W39="","Decision Maker",""))) -> ⚠ MISSING: Call Date, Modality, Budget, Timeline, Decision Maker | AC39: Dead — Not a Fit | AD39: Not a Fit
A40: =IF(C40<>"","AYA-"&TEXT(ROW()-5,"000"),"") -> AYA-035 | B40: 45708.476 | C40: University | D40: Hospital | F40: marketing@uhnj.org | G40: University Hospital | J40: Google Ads | M40: 45708.476 | N40: No Response | P40: LiDAR Annotation | Q40: Direct | Y40: Awaiting feedback - No response | Z40: =IF(C40="","",(IF(OR(P40="Data Annotation",P40="GenAI / LLM Eval",P40="Medical Annotation"),25,IF(OR(P40="AI Consulting",P40="Data Collection"),18,IF(P40<>"",10,0)))+IF(AND(K40<>"",LEN(K40)>50,T40<>""),20,IF(AND(K40<>"",LEN(K40)>20),12,IF(K40<>"",5,0)))+IF(OR(U40="$100k–$500k",U40="$500k+"),20,IF(OR(U40="$25k–$100k"),15,IF(OR(U40="$5k–$25k"),10,IF(U40="$1k–$5k",5,0))))+IF(AND(G40<>"",G40<>"-"),15,IF(G40<>"",8,0))+IF(V40="Immediate (this month)",10,IF(V40="Short-term (1–3 months)",7,IF(V40="Medium (3–6 months)",4,0)))+IF(W40="Yes",10,IF(W40="Unclear",5,0)))) -> 25 | AA40: =IF(Z40="","",IF(Z40>=75,"A",IF(Z40>=50,"B",IF(Z40>=25,"C","D")))) -> C | AB40: =IF(C40="","",IF(AND(R40<>"",S40<>"",U40<>"",V40<>"",W40<>""),"✓ Complete","⚠ MISSING: "&IF(R40="","Call Date, ","")&IF(S40="","Modality, ","")&IF(U40="","Budget, ","")&IF(V40="","Timeline, ","")&IF(W40="","Decision Maker",""))) -> ⚠ MISSING: Call Date, Modality, Budget, Timeline, Decision Maker | AC40: Dead — No Response | AD40: No Response
A41: =IF(C41<>"","AYA-"&TEXT(ROW()-5,"000"),"") -> AYA-036 | B41: 45709 | C41: Sofia | D41: Ovejero | F41: sofia.ovejero@dedalus.com | G41: Dedalus | J41: Search Engine | K41: I am writing to request a quote for clinical labelling/data annotation project support based on the following requirements [see Marketing chat for more details] | L41: Akhil | M41: 45709 | O41: Data Annotation | Q41: Direct | X41: Healthcare/Medical | Y41: Client put the project on hold! | Z41: =IF(C41="","",(IF(OR(P41="Data Annotation",P41="GenAI / LLM Eval",P41="Medical Annotation"),25,IF(OR(P41="AI Consulting",P41="Data Collection"),18,IF(P41<>"",10,0)))+IF(AND(K41<>"",LEN(K41)>50,T41<>""),20,IF(AND(K41<>"",LEN(K41)>20),12,IF(K41<>"",5,0)))+IF(OR(U41="$100k–$500k",U41="$500k+"),20,IF(OR(U41="$25k–$100k"),15,IF(OR(U41="$5k–$25k"),10,IF(U41="$1k–$5k",5,0))))+IF(AND(G41<>"",G41<>"-"),15,IF(G41<>"",8,0))+IF(V41="Immediate (this month)",10,IF(V41="Short-term (1–3 months)",7,IF(V41="Medium (3–6 months)",4,0)))+IF(W41="Yes",10,IF(W41="Unclear",5,0)))) -> 27 | AA41: =IF(Z41="","",IF(Z41>=75,"A",IF(Z41>=50,"B",IF(Z41>=25,"C","D")))) -> C | AB41: =IF(C41="","",IF(AND(R41<>"",S41<>"",U41<>"",V41<>"",W41<>""),"✓ Complete","⚠ MISSING: "&IF(R41="","Call Date, ","")&IF(S41="","Modality, ","")&IF(U41="","Budget, ","")&IF(V41="","Timeline, ","")&IF(W41="","Decision Maker",""))) -> ⚠ MISSING: Call Date, Modality, Budget, Timeline, Decision Maker | AC41: Dead — No Budget | AD41: Project on Hold
